Workbook

Sheet frente
A1: 1 | B1: 2 | C1: 3 | D1: 4 | E1: 5
A2: SR1011 | B2: Termo Cuidar 700ml Blanco | C2: 11389.84 | D2: 6 | E2: 0.00445625 | M2: 0.00445625
A3: SR1011/1 | B3: Termo Cuidar 700ml Negro | C3: 11389.84 | D3: 6 | E3: 0.00445625 | M3: 0.00445625 | O3: =VLOOKUP(A446;'C:\Users\Lenovo\Downloads\[OC saldo promoción (JENE).xlsx]PORTFOLIO - SANREMO'!C$3:J$772;8;FALSE)
A4: SR1011/60 | B4: Termo Cuidar 700ml + Porta Filtro en Caja de Regalo Rosa | C4: 16108.488 | D4: 6 | E4: 0.009084375 | M4: 0.009084375
A5: SR1011/61 | B5: Termo Cuidar 700ml + Porta Filtro en Caja de Regalo Blanco | C5: 16108.488 | D5: 6 | E5: 0.009084375 | M5: 0.009084375
A6: SR1015/3 | B6: Termo Bomba Expressar 1L Rojo | C6: 20339 | D6: 6 | E6: 0.00684375 | M6: 0.00684375
A7: SR1015/50 | B7: Termo Bomba Expressar Negro 1L Con Serigrafía"Café" | C7: 20339 | D7: 6 | E7: 0.009 | M7: 0.009
A8: SR1015/51 | B8: Termo Bomba Expressar Blanco 1L Con Serigrafía "Leche" | C8: 20339 | D8: 6 | E8: 0.009 | M8: 0.009
A9: SR1016 | B9: Termo Bomba Expressar de 1.8 lts. Blanco | C9: 21966.12 | D9: 6 | E9: 0.0095 | M9: 0.0095
A10: SR1016/1 | B10: Termo Bomba Expressar de 1.8 lts. Negro | C10: 21966.12 | D10: 6 | E10: 0.0095 | M10: 0.0095
A11: SR1016/A | B11: Ampolla Repuesto 1.8lts. | C11: 14644.08 | D11: 6 | E11: 0.0061425 | M11: 0.0061425
A12: SR1001 | B12: Termo Adorar 0.25lts. Blanco | C12: 9762.72 | D12: 6 | E12: 0.00170925 | M12: 0.00170925
A13: SR1001/1 | B13: Termo Adorar 0.25lts. Negro | C13: 9762.72 | D13: 6 | E13: 0.00170925 | M13: 0.00170925
A14: SR1001/2 | B14: Termo Adorar 0.25lts. Celeste | C14: 9762.72 | D14: 6 | E14: 0.00170925 | M14: 0.00170925
A15: SR1001/3 | B15: Termo Adorar 0.25lts. Rosa | C15: 9762.72 | D15: 6 | E15: 0.00170925 | M15: 0.00170925
E16: #N/A | M16: #N/A
A17: 1763/33 | B17: Rectangular de 330ml 136X102X56Mm | C17: 2359.324 | D17: 12 | E17: 0.0007409 | F17: #REF! | G17: #REF! | H17: #REF! | I17: #REF! | J17: #REF! | K17: #REF! | L17: #REF! | M17: 0.0007409
A18: 1762/33 | B18: Rectangular Alto de 537ml 136X102X84Mm | C18: 2522.036 | D18: 12 | E18: 0.0010465 | F18: #REF! | G18: #REF! | H18: #REF! | I18: #REF! | J18: #REF! | K18: #REF! | L18: #REF! | M18: 0.0010465
A19: 1761/33 | B19: Rectangular Alto de 770ml 136X102X110Mm | C19: 3091.528 | D19: 12 | E19: 0.001468125 | F19: #REF! | G19: #REF! | H19: #REF! | I19: #REF! | J19: #REF! | K19: #REF! | L19: #REF! | M19: 0.001468125
A20: 1760/33 | B20: Rectangular Alto de 1400ml 136X102X185Mm | C20: 3579.664 | D20: 6 | E20: 0.0025175 | F20: #REF! | G20: #REF! | H20: #REF! | I20: #REF! | J20: #REF! | K20: #REF! | L20: #REF! | M20: 0.0025175
A21: 1753/33 | B21: Rectangular c/División de 730ml 207X137X57Mm | C21: 3538.986 | D21: 12 | E21: 0.0015708 | F21: #REF! | G21: #REF! | H21: #REF! | I21: #REF! | J21: #REF! | K21: #REF! | L21: #REF! | M21: 0.0015708
A22: 1752/33 | B22: Rectangular de 820ml 207X137X57Mm | C22: 3416.952 | D22: 12 | E22: 0.0015708 | F22: #REF! | G22: #REF! | H22: #REF! | I22: #REF! | J22: #REF! | K22: #REF! | L22: #REF! | M22: 0.0015708
A23: 1751/33 | B23: Rectangular de 1240ml 207X137X76Mm | C23: 3742.376 | D23: 12 | E23: 0.00221375 | F23: #REF! | G23: #REF! | H23: #REF! | I23: #REF! | J23: #REF! | K23: #REF! | L23: #REF! | M23: 0.00221375
A24: 1750/33 | B24: Rectangular de 2000ml 207X137X113Mm | C24: 4393.224 | D24: 6 | E24: 0.003542 | F24: #REF! | G24: #REF! | H24: #REF! | I24: #REF! | J24: #REF! | K24: #REF! | L24: #REF! | M24: 0.003542
A25: 1742/34 | B25: Rectangular c/División de 1600ml 253X174X62Mm | C25: 5369.496 | D25: 6 | E25: 0.002843375 | F25: #REF! | G25: #REF! | H25: #REF! | I25: #REF! | J25: #REF! | K25: #REF! | L25: #REF! | M25: 0.002843375
A26: 1742/33 | B26: Rectangular de 1600ml 253X174X62Mm | C26: 4718.648 | D26: 6 | E26: 0.002843675 | F26: #REF! | G26: #REF! | H26: #REF! | I26: #REF! | J26: #REF! | K26: #REF! | L26: #REF! | M26: 0.002843675
A27: 1741/33 | B27: Rectangular de 2500ml 253X174X89Mm | C27: 5044.072 | D27: 6 | E27: 0.00420875 | F27: #REF! | G27: #REF! | H27: #REF! | I27: #REF! | J27: #REF! | K27: #REF! | L27: #REF! | M27: 0.00420875
A28: 1740/33 | B28: Rectangular de 3500ml 253X174X122Mm | C28: 5369.496 | D28: 6 | E28: 0.005465625 | F28: #REF! | G28: #REF! | H28: #REF! | I28: #REF! | J28: #REF! | K28: #REF! | L28: #REF! | M28: 0.005465625
A29: 1741/33/C | B29: Set x 3 Herméticos (1741+1751+1763) | C29: 9844.076 | D29: 6 | E29: 0.00420875 | F29: #REF! | G29: #REF! | H29: #REF! | I29: #REF! | J29: #REF! | K29: #REF! | L29: #REF! | M29: 0.00420875
A30: 1763 | B30: Rectangular de 330ml 136X102X56Mm | C30: 2359.324 | D30: 12 | E30: 0.0007409 | F30: #REF! | G30: #REF! | H30: #REF! | I30: #REF! | J30: #REF! | K30: #REF! | L30: #REF! | M30: 0.0007409
A31: 1762 | B31: Rectangular Alto de 537ml 136X102X84Mm | C31: 2522.036 | D31: 12 | E31: 0.0010465 | F31: #REF! | G31: #REF! | H31: #REF! | I31: #REF! | J31: #REF! | K31: #REF! | L31: #REF! | M31: 0.0010465
A32: 1761 | B32: Rectangular Alto de 770ml 136X102X110Mm | C32: 3091.528 | D32: 12 | E32: 0.001468125 | F32: #REF! | G32: #REF! | H32: #REF! | I32: #REF! | J32: #REF! | K32: #REF! | L32: #REF! | M32: 0.001468125
A33: 1760 | B33: Rectangular Alto de 1400ml 136X102X185Mm | C33: 3579.664 | D33: 6 | E33: 0.0025175 | F33: #REF! | G33: #REF! | H33: #REF! | I33: #REF! | J33: #REF! | K33: #REF! | L33: #REF! | M33: 0.0025175
A34: 1753 | B34: Rectangular c/División de 730ml 207X137X57Mm | C34: 3538.986 | D34: 12 | E34: 0.0015708 | M34: 0.0015708
A35: 1752 | B35: Rectangular de 820ml 207X137X57Mm | C35: 3416.952 | D35: 12 | E35: 0.0015708 | F35: #REF! | G35: #REF! | H35: #REF! | I35: #REF! | J35: #REF! | K35: #REF! | L35: #REF! | M35: 0.0015708
A36: 1751 | B36: Rectangular de 1240ml 207X137X76Mm | C36: 3742.376 | D36: 12 | E36: 0.00221375 | F36: #REF! | G36: #REF! | H36: #REF! | I36: #REF! | J36: #REF! | K36: #REF! | L36: #REF! | M36: 0.00221375
A37: 1750 | B37: Rectangular de 2000ml 207X137X113Mm | C37: 4393.224 | D37: 6 | E37: 0.003542 | F37: #REF! | G37: #REF! | H37: #REF! | I37: #REF! | J37: #REF! | K37: #REF! | L37: #REF! | M37: 0.003542
A38: 1742 | B38: Rectangular de 1600ml 253X174X62Mm | C38: 4718.648 | D38: 6 | E38: 0.002843675 | F38: #REF! | G38: #REF! | H38: #REF! | I38: #REF! | J38: #REF! | K38: #REF! | L38: #REF! | M38: 0.002843675
A39: 1742/22 | B39: Rectangular c/División de 1600ml 253X174X62Mm | C39: 5369.496 | D39: 6 | E39: 0.002843375 | F39: #REF! | G39: #REF! | H39: #REF! | I39: #REF! | J39: #REF! | K39: #REF! | L39: #REF! | M39: 0.002843375
A40: 1741 | B40: Rectangular de 2500ml 253X174X89Mm | C40: 5044.072 | D40: 6 | E40: 0.00420875 | F40: #REF! | G40: #REF! | H40: #REF! | I40: #REF! | J40: #REF! | K40: #REF! | L40: #REF! | M40: 0.00420875
...

Sheet Pedido
A1: Cliente: | B1: Bottega | E1: N° Cta.: | F1: 9067 | H1: Observaciones:
A2: Dirección: | E2: Fecha: | F2: =TODAY() -> 46185 | S2: Lista
A3: Horarios de entrega / mail: | E3: Número: | F3: 37653 | S3: 1
A4: Tpte: | D4: Total bultos | F4: =SUM(G10:G9966) -> 9 | G4: ="m2=>"&ROUND(SUM(J10:J199),2) -> m2=>0,02 | S4: 13
A5: Lista: | B5: 1 | D5: Subtotal: | F5: =SUM(F10:F9965) -> 290733.8
C6: NOTA DE PEDIDO | D6: Bonificación: | E6: 0.1 | F6: =-F5*E6 -> -29073.38
C7: E-mail: info@bmimport.com.ar | D7: Bonificación: | F7: =-(F5+F6)*E7 -> 0
D8: Total: | F8: =SUM(F5:F7) -> 261660.42
A9: Código | B9: Cantidad | C9: Descripción | D9: Precio | E9: UxC | F9: Total $ | G9: Total bultos
A10: 12310 | B10: 2 | C10: =IFERROR(IF(A10>0,VLOOKUP(A10,frente!A$3:E$10001,2,FALSE)," "),"") -> Guisera 26cm. Con Tapa de Vidrio | D10: =IFERROR(IF(A10>0,VLOOKUP(A10,frente!A$3:F$10001,3,FALSE)," "),"") -> 46698.344 | E10: =IFERROR(IF(A10>0,VLOOKUP(A10,frente!A$3:F$10001,4,FALSE)," "),"") -> 1 | F10: =IFERROR(IF(A10>0,B10*D10," "),"") -> 93396.688 | G10: =IFERROR(IF(A10>0,B10/E10," "),"") -> 2 | J10: =IFERROR(IF(A10>0,VLOOKUP(A10,[1]frente!A$3:E$10000,5,FALSE)*B10," "),"")
A11: 793 | B11: 12 | C11: =IFERROR(IF(A11>0,VLOOKUP(A11,[1]frente!A$3:E$10000,2,FALSE)," "),"") -> Jarra Exprimidor 1,00 lts. | D11: =IFERROR(IF(A11>0,VLOOKUP(A11,[1]frente!A$3:F$10000,3,FALSE)," "),"") -> 3164.7484 | E11: =IFERROR(IF(A11>0,VLOOKUP(A11,[1]frente!A$3:F$10000,4,FALSE)," "),"") -> 12 | F11: =IFERROR(IF(A11>0,B11*D11," "),"") -> 37976.981 | G11: =IFERROR(IF(A11>0,B11/E11," "),"") -> 1 | J11: =IFERROR(IF(A11>0,VLOOKUP(A11,[1]frente!A$3:E$10000,5,FALSE)*B11," "),"") -> 0.024320244
A12: 12819 | B12: 2 | C12: =IFERROR(IF(A12>0,VLOOKUP(A12,[1]frente!A$3:E$10000,2,FALSE)," "),"") -> Sartenes 20cm. | D12: =IFERROR(IF(A12>0,VLOOKUP(A12,[1]frente!A$3:F$10000,3,FALSE)," "),"") -> 22519.341 | E12: =IFERROR(IF(A12>0,VLOOKUP(A12,[1]frente!A$3:F$10000,4,FALSE)," "),"") -> 1 | F12: =IFERROR(IF(A12>0,B12*D12," "),"") -> 45038.682 | G12: =IFERROR(IF(A12>0,B12/E12," "),"") -> 2 | J12: =IFERROR(IF(A12>0,VLOOKUP(A12,[1]frente!A$3:E$10000,5,FALSE)*B12," "),"")
A13: 12820 | B13: 2 | C13: =IFERROR(IF(A13>0,VLOOKUP(A13,[1]frente!A$3:E$10000,2,FALSE)," "),"") -> Sartenes 22cm. | D13: =IFERROR(IF(A13>0,VLOOKUP(A13,[1]frente!A$3:F$10000,3,FALSE)," "),"") -> 23397.986 | E13: =IFERROR(IF(A13>0,VLOOKUP(A13,[1]frente!A$3:F$10000,4,FALSE)," "),"") -> 1 | F13: =IFERROR(IF(A13>0,B13*D13," "),"") -> 46795.971 | G13: =IFERROR(IF(A13>0,B13/E13," "),"") -> 2 | J13: =IFERROR(IF(A13>0,VLOOKUP(A13,[1]frente!A$3:E$10000,5,FALSE)*B13," "),"")
A14: 12823 | B14: 2 | C14: =IFERROR(IF(A14>0,VLOOKUP(A14,[1]frente!A$3:E$10000,2,FALSE)," "),"") -> Sartenes 28cm. | D14: =IFERROR(IF(A14>0,VLOOKUP(A14,[1]frente!A$3:F$10000,3,FALSE)," "),"") -> 33762.74 | E14: =IFERROR(IF(A14>0,VLOOKUP(A14,[1]frente!A$3:F$10000,4,FALSE)," "),"") -> 1 | F14: =IFERROR(IF(A14>0,B14*D14," "),"") -> 67525.48 | G14: =IFERROR(IF(A14>0,B14/E14," "),"") -> 2 | J14: =IFERROR(IF(A14>0,VLOOKUP(A14,[1]frente!A$3:E$10000,5,FALSE)*B14," "),"")
C15: =IFERROR(IF(A15>0,VLOOKUP(A15,[1]frente!A$3:E$10000,2,FALSE)," "),"") | D15: =IFERROR(IF(A15>0,VLOOKUP(A15,[1]frente!A$3:F$10000,3,FALSE)," "),"") | E15: =IFERROR(IF(A15>0,VLOOKUP(A15,[1]frente!A$3:F$10000,4,FALSE)," "),"") | F15: =IFERROR(IF(A15>0,B15*D15," "),"") | G15: =IFERROR(IF(A15>0,B15/E15," "),"") | J15: =IFERROR(IF(A15>0,VLOOKUP(A15,[1]frente!A$3:E$10000,5,FALSE)*B15," "),"")
C16: =IFERROR(IF(A16>0,VLOOKUP(A16,[1]frente!A$3:E$10000,2,FALSE)," "),"") | D16: =IFERROR(IF(A16>0,VLOOKUP(A16,[1]frente!A$3:F$10000,3,FALSE)," "),"") | E16: =IFERROR(IF(A16>0,VLOOKUP(A16,[1]frente!A$3:F$10000,4,FALSE)," "),"") | F16: =IFERROR(IF(A16>0,B16*D16," "),"") | G16: =IFERROR(IF(A16>0,B16/E16," "),"") | J16: =IFERROR(IF(A16>0,VLOOKUP(A16,[1]frente!A$3:E$10000,5,FALSE)*B16," "),"")
C17: =IFERROR(IF(A17>0,VLOOKUP(A17,[1]frente!A$3:E$10000,2,FALSE)," "),"") | D17: =IFERROR(IF(A17>0,VLOOKUP(A17,[1]frente!A$3:F$10000,3,FALSE)," "),"") | E17: =IFERROR(IF(A17>0,VLOOKUP(A17,[1]frente!A$3:F$10000,4,FALSE)," "),"") | F17: =IFERROR(IF(A17>0,B17*D17," "),"") | G17: =IFERROR(IF(A17>0,B17/E17," "),"") | J17: =IFERROR(IF(A17>0,VLOOKUP(A17,[1]frente!A$3:E$10000,5,FALSE)*B17," "),"")
C18: =IFERROR(IF(A18>0,VLOOKUP(A18,[1]frente!A$3:E$10000,2,FALSE)," "),"") | D18: =IFERROR(IF(A18>0,VLOOKUP(A18,[1]frente!A$3:F$10000,3,FALSE)," "),"") | E18: =IFERROR(IF(A18>0,VLOOKUP(A18,[1]frente!A$3:F$10000,4,FALSE)," "),"") | F18: =IFERROR(IF(A18>0,B18*D18," "),"") | G18: =IFERROR(IF(A18>0,B18/E18," "),"") | J18: =IFERROR(IF(A18>0,VLOOKUP(A18,[1]frente!A$3:E$10000,5,FALSE)*B18," "),"")
C19: =IFERROR(IF(A19>0,VLOOKUP(A19,[1]frente!A$3:E$10000,2,FALSE)," "),"") | D19: =IFERROR(IF(A19>0,VLOOKUP(A19,[1]frente!A$3:F$10000,3,FALSE)," "),"") | E19: =IFERROR(IF(A19>0,VLOOKUP(A19,[1]frente!A$3:F$10000,4,FALSE)," "),"") | F19: =IFERROR(IF(A19>0,B19*D19," "),"") | G19: =IFERROR(IF(A19>0,B19/E19," "),"") | J19: =IFERROR(IF(A19>0,VLOOKUP(A19,[1]frente!A$3:E$10000,5,FALSE)*B19," "),"")
C20: =IFERROR(IF(A20>0,VLOOKUP(A20,[1]frente!A$3:E$10000,2,FALSE)," "),"") | D20: =IFERROR(IF(A20>0,VLOOKUP(A20,[1]frente!A$3:F$10000,3,FALSE)," "),"") | E20: =IFERROR(IF(A20>0,VLOOKUP(A20,[1]frente!A$3:F$10000,4,FALSE)," "),"") | F20: =IFERROR(IF(A20>0,B20*D20," "),"") | G20: =IFERROR(IF(A20>0,B20/E20," "),"") | J20: =IFERROR(IF(A20>0,VLOOKUP(A20,[1]frente!A$3:E$10000,5,FALSE)*B20," "),"")
C21: =IFERROR(IF(A21>0,VLOOKUP(A21,[1]frente!A$3:E$10000,2,FALSE)," "),"") | D21: =IFERROR(IF(A21>0,VLOOKUP(A21,[1]frente!A$3:F$10000,3,FALSE)," "),"") | E21: =IFERROR(IF(A21>0,VLOOKUP(A21,[1]frente!A$3:F$10000,4,FALSE)," "),"") | F21: =IFERROR(IF(A21>0,B21*D21," "),"") | G21: =IFERROR(IF(A21>0,B21/E21," "),"") | J21: =IFERROR(IF(A21>0,VLOOKUP(A21,[1]frente!A$3:E$10000,5,FALSE)*B21," "),"")
C22: =IFERROR(IF(A22>0,VLOOKUP(A22,[1]frente!A$3:E$10000,2,FALSE)," "),"") | D22: =IFERROR(IF(A22>0,VLOOKUP(A22,[1]frente!A$3:F$10000,3,FALSE)," "),"") | E22: =IFERROR(IF(A22>0,VLOOKUP(A22,[1]frente!A$3:F$10000,4,FALSE)," "),"") | F22: =IFERROR(IF(A22>0,B22*D22," "),"") | G22: =IFERROR(IF(A22>0,B22/E22," "),"") | J22: =IFERROR(IF(A22>0,VLOOKUP(A22,[1]frente!A$3:E$10000,5,FALSE)*B22," "),"")
C23: =IFERROR(IF(A23>0,VLOOKUP(A23,[1]frente!A$3:E$10000,2,FALSE)," "),"") | D23: =IFERROR(IF(A23>0,VLOOKUP(A23,[1]frente!A$3:F$10000,3,FALSE)," "),"") | E23: =IFERROR(IF(A23>0,VLOOKUP(A23,[1]frente!A$3:F$10000,4,FALSE)," "),"") | F23: =IFERROR(IF(A23>0,B23*D23," "),"") | G23: =IFERROR(IF(A23>0,B23/E23," "),"") | J23: =IFERROR(IF(A23>0,VLOOKUP(A23,[1]frente!A$3:E$10000,5,FALSE)*B23," "),"")
C24: =IFERROR(IF(A24>0,VLOOKUP(A24,[1]frente!A$3:E$10000,2,FALSE)," "),"") | D24: =IFERROR(IF(A24>0,VLOOKUP(A24,[1]frente!A$3:F$10000,3,FALSE)," "),"") | E24: =IFERROR(IF(A24>0,VLOOKUP(A24,[1]frente!A$3:F$10000,4,FALSE)," "),"") | F24: =IFERROR(IF(A24>0,B24*D24," "),"") | G24: =IFERROR(IF(A24>0,B24/E24," "),"") | J24: =IFERROR(IF(A24>0,VLOOKUP(A24,[1]frente!A$3:E$10000,5,FALSE)*B24," "),"")
C25: =IFERROR(IF(A25>0,VLOOKUP(A25,[1]frente!A$3:E$10000,2,FALSE)," "),"") | D25: =IFERROR(IF(A25>0,VLOOKUP(A25,[1]frente!A$3:F$10000,3,FALSE)," "),"") | E25: =IFERROR(IF(A25>0,VLOOKUP(A25,[1]frente!A$3:F$10000,4,FALSE)," "),"") | F25: =IFERROR(IF(A25>0,B25*D25," "),"") | G25: =IFERROR(IF(A25>0,B25/E25," "),"") | J25: =IFERROR(IF(A25>0,VLOOKUP(A25,[1]frente!A$3:E$10000,5,FALSE)*B25," "),"")
C26: =IFERROR(IF(A26>0,VLOOKUP(A26,[1]frente!A$3:E$10000,2,FALSE)," "),"") | D26: =IFERROR(IF(A26>0,VLOOKUP(A26,[1]frente!A$3:F$10000,3,FALSE)," "),"") | E26: =IFERROR(IF(A26>0,VLOOKUP(A26,[1]frente!A$3:F$10000,4,FALSE)," "),"") | F26: =IFERROR(IF(A26>0,B26*D26," "),"") | G26: =IFERROR(IF(A26>0,B26/E26," "),"") | J26: =IFERROR(IF(A26>0,VLOOKUP(A26,[1]frente!A$3:E$10000,5,FALSE)*B26," "),"")
... C199: =IFERROR(IF(A199>0,VLOOKUP(A199,[1]frente!A$3:E$10000,2,FALSE)," "),"") | D199: =IFERROR(IF(A199>0,VLOOKUP(A199,[1]frente!A$3:F$10000,3,FALSE)," "),"") | E199: =IFERROR(IF(A199>0,VLOOKUP(A199,[1]frente!A$3:F$10000,4,FALSE)," "),"") | F199: =IFERROR(IF(A199>0,B199*D199," "),"") | G199: =IFERROR(IF(A199>0,B199/E199," "),"") | J199: =IFERROR(IF(A199>0,VLOOKUP(A199,[1]frente!A$3:E$10000,5,FALSE)*B199," "),"")

Sheet csv
A1: . | B1: Dato Obligatorio | F1: Cliente: | G1: =+Pedido!C1 -> 0
A2: . | B2: Dato Opcional | F2: Código: | G2: =+Pedido!F1 -> 9067
A3: . | B3: Dato Condicional
A4: .
A5: .
A6: ARTICULO | B6: NOMBRE ARTICULO | C6: DEPOSITO | D6: UM | E6: CANTIDAD | F6: FECHA DE ENTREGA | G6: LISTA DE PRECIO | H6: PRECIO | I6: DESCUENTO 1 | J6: DESCUENTO 2 | K6: DESCUENTO 3 | L6: DESCUENTO 4 | M6: DESCRIPCION | N6: CLASIFICACION DE PARTIDAS 1 | O6: CLASIFICACION DE PARTIDAS 2 | P6: CLASIFICACION DE PARTIDAS 3 | Q6: CLASIFICACION DE PARTIDAS 4 | R6: CLASIFICACION DE PARTIDAS 5 | S6: CLASIFICACION DE PARTIDAS 6 | T6: CLASIFICACION DE PARTIDAS 7 | U6: CLASIFICACION DE PARTIDAS 8
A7: =+Pedido!A10 -> 12310 | C7: 1 | D7: UN | E7: =+Pedido!B10 -> 2
A8: =+Pedido!A11 -> 793 | C8: 1 | D8: UN | E8: =+Pedido!B11 -> 12
A9: =+Pedido!A12 -> 12819 | C9: 1 | D9: UN | E9: =+Pedido!B12 -> 2
A10: =+Pedido!A13 -> 12820 | C10: 1 | D10: UN | E10: =+Pedido!B13 -> 2
A11: =+Pedido!A14 -> 12823 | C11: 1 | D11: UN | E11: =+Pedido!B14 -> 2
A12: =+Pedido!A15 -> 0 | C12: 1 | D12: UN | E12: =+Pedido!B15 -> 0
A13: =+Pedido!A16 -> 0 | C13: 1 | D13: UN | E13: =+Pedido!B16 -> 0
A14: =+Pedido!A17 -> 0 | C14: 1 | D14: UN | E14: =+Pedido!B17 -> 0
A15: =+Pedido!A18 -> 0 | C15: 1 | D15: UN | E15: =+Pedido!B18 -> 0
A16: =+Pedido!A19 -> 0 | C16: 1 | D16: UN | E16: =+Pedido!B19 -> 0
A17: =+Pedido!A20 -> 0 | C17: 1 | D17: UN | E17: =+Pedido!B20 -> 0
A18: =+Pedido!A21 -> 0 | C18: 1 | D18: UN | E18: =+Pedido!B21 -> 0
... A500: =+Pedido!A503 -> 0 | C500: 1 | D500: UN | E500: =+Pedido!B503 -> 0
